Workbook

Sheet Cover
W4: Hallo
D5: Gale Suer
D6: Financial Analyst
D12: SaaS Operating, 3-Statement & Valuation Financial Model
D13: Anarion Systems BV | 24-Month Driver-Based Forecast
D17: Table of Contents | L17: Model Integrity Checks
D19: Executive Dashboard | L19: Cash Flow Statement | R19: =IF(SUM('Operational Model'!G78:AD78)<>0,1,0) -> 0
D20: Inputs | L20: Balance Sheet | R20: =IF(SUM('Operational Model'!G118:AD118)<>0,1,0) -> 0
D21: Operational Model | L21: Revenue Forecast | R21: =IF(SUM('Operational Model'!G166:AD166)<>0,1,0) -> 0
D22: Valuation | L22: Headcount Forecast | R22: =IF(SUM('Operational Model'!G263:AD264)<>0,1,0) -> 0
L23: Cash & Fundraising Analysis | R23: =IF(SUM('Operational Model'!G345:AD349)<>0,1,0) -> 0
L24: Deferred Revenue Schedule | R24: =IF(SUM('Operational Model'!G422:AD423)<>0,1,0) -> 0
L25: PP&E & Depreciation Schedule | R25: =IF(SUM('Operational Model'!G464:AD464)<>0,1,0) -> 0
D30: Contact Details: | L30: Core Capabilities
D32: Tel. | E32: +31648370031 | L32: Driver-Based Forecasting · SaaS Metrics & KPI Reporting · Headcount Planning
D33: E-mail | E33: Gale.suer@outlook.com | L33: Cash & Runway Analysis · Scenario & Sensitivity Analysis · Business Valuation

Sheet Executive Dashboard
B1: Gale Suer - Financial Analyst
B3: Growth Performance | AB3: Graphing Data
B5: All figures in EUR thousands unless stated | AB5: All figures in EUR thousands unless stated | AF5: 2026 | AG5: 2026 | AH5: 2026 | AI5: 2026 | AJ5: 2026 | AK5: 2026 | AL5: 2026 | AM5: 2026 | AN5: 2026 | AO5: 2026 | AP5: 2026 | AQ5: 2026 | AR5: 2027 | AS5: 2027 | AT5: 2027 | AU5: 2027 | AV5: 2027 | AW5: 2027 | AX5: 2027 | AY5: 2027 | AZ5: 2027 | BA5: 2027 | BB5: 2027 | BC5: 2027
AF6: 1 | AG6: 1 | AH6: 1 | AI6: 2 | AJ6: 2 | AK6: 2 | AL6: 3 | AM6: 3 | AN6: 3 | AO6: 4 | AP6: 4 | AQ6: 4 | AR6: 1 | AS6: 1 | AT6: 1 | AU6: 2 | AV6: 2 | AW6: 2 | AX6: 3 | AY6: 3 | AZ6: 3 | BA6: 4 | BB6: 4 | BC6: 4
B7: Driver Switch | AF7: 46053 | AG7: 46081 | AH7: 46112 | AI7: 46142 | AJ7: 46173 | AK7: 46203 | AL7: 46234 | AM7: 46265 | AN7: 46295 | AO7: 46326 | AP7: 46356 | AQ7: 46387 | AR7: 46418 | AS7: 46446 | AT7: 46477 | AU7: 46507 | AV7: 46538 | AW7: 46568 | AX7: 46599 | AY7: 46630 | AZ7: 46660 | BA7: 46691 | BB7: 46721 | BC7: 46752
C10: Monthly Recurring Revenue | P10: Annual Recurring Revenue | AB10: Growth Performance
AB11: MRR | AF11: ='Operational Model'!G155 -> 913.2228 | AG11: ='Operational Model'!H155 -> 933.64625 | AH11: ='Operational Model'!I155 -> 953.82026 | AI11: ='Operational Model'!J155 -> 973.79366 | AJ11: ='Operational Model'!K155 -> 993.61427 | AK11: ='Operational Model'!L155 -> 1013.329 | AL11: ='Operational Model'!M155 -> 1032.9839 | AM11: ='Operational Model'!N155 -> 1052.6242 | ... BC11: ='Operational Model'!AD155 -> 1461.3423
AB12: MRR Growth | AF12: ='Operational Model'!G156 -> 0.023218824 | AG12: ='Operational Model'!H156 -> 0.022364149 | AH12: ='Operational Model'!I156 -> 0.021607766 | AI12: ='Operational Model'!J156 -> 0.020940422 | AJ12: ='Operational Model'!K156 -> 0.02035402 | AK12: ='Operational Model'!L156 -> 0.019841432 | AL12: ='Operational Model'!M156 -> 0.019396351 | AM12: ='Operational Model'!N156 -> 0.019013163 | ... BC12: ='Operational Model'!AD156 -> 0.020881645
AB13: ARR | AF13: ='Operational Model'!G163 -> 10958.674 | AG13: ='Operational Model'!H163 -> 11203.755 | AH13: ='Operational Model'!I163 -> 11445.843 | AI13: ='Operational Model'!J163 -> 11685.524 | AJ13: ='Operational Model'!K163 -> 11923.371 | AK13: ='Operational Model'!L163 -> 12159.948 | AL13: ='Operational Model'!M163 -> 12395.807 | AM13: ='Operational Model'!N163 -> 12631.49 | ... BC13: ='Operational Model'!AD163 -> 17536.108
AB14: ARR Growth | AF14: ='Operational Model'!G164 -> 0.023218824 | AG14: ='Operational Model'!H164 -> 0.022364149 | AH14: ='Operational Model'!I164 -> 0.021607766 | AI14: ='Operational Model'!J164 -> 0.020940422 | AJ14: ='Operational Model'!K164 -> 0.02035402 | AK14: ='Operational Model'!L164 -> 0.019841432 | AL14: ='Operational Model'!M164 -> 0.019396351 | AM14: ='Operational Model'!N164 -> 0.019013163 | ... BC14: ='Operational Model'!AD164 -> 0.020881645
AB21: New MRR | AF21: ='Operational Model'!G151 -> 36.75 | AG21: ='Operational Model'!H151 -> 36.824342 | AH21: ='Operational Model'!I151 -> 36.943102 | AI21: ='Operational Model'!J151 -> 37.106104 | AJ21: ='Operational Model'!K151 -> 37.313227 | AK21: ='Operational Model'!L151 -> 37.564403 | AL21: ='Operational Model'!M151 -> 37.859621 | AM21: ='Operational Model'!N151 -> 38.198922 | ... BC21: ='Operational Model'!AD151 -> 51.286265
AB22: Lost MRR | AF22: ='Operational Model'!G152 -> -17.85 | AG22: ='Operational Model'!H152 -> -18.264456 | AH22: ='Operational Model'!I152 -> -18.672925 | AI22: ='Operational Model'!J152 -> -19.076405 | AJ22: ='Operational Model'!K152 -> -19.475873 | AK22: ='Operational Model'!L152 -> -19.872285 | AL22: ='Operational Model'!M152 -> -20.26658 | AM22: ='Operational Model'!N152 -> -20.659678 | ... BC22: ='Operational Model'!AD152 -> -25.766123
AB23: Net New MRR | AF23: ='Operational Model'!G153 -> 18.9 | AG23: ='Operational Model'!H153 -> 18.559886 | AH23: ='Operational Model'!I153 -> 18.270177 | AI23: ='Operational Model'!J153 -> 18.029699 | AJ23: ='Operational Model'!K153 -> 17.837353 | AK23: ='Operational Model'!L153 -> 17.692118 | AL23: ='Operational Model'!M153 -> 17.593041 | AM23: ='Operational Model'!N153 -> 17.539244 | ... BC23: ='Operational Model'!AD153 -> 25.520142
C37: MRR Inflow/Outflow | P37: MRR Inflow/Outflow
B65: Customer Growth & Retention | AB65: Graphing Data
B67: All figures in EUR thousands unless stated | AB67: All figures in EUR thousands unless stated | AF67: 2026 | AG67: 2026 | AH67: 2026 | AI67: 2026 | AJ67: 2026 | AK67: 2026 | AL67: 2026 | AM67: 2026 | AN67: 2026 | AO67: 2026 | AP67: 2026 | AQ67: 2026 | AR67: 2027 | AS67: 2027 | AT67: 2027 | AU67: 2027 | AV67: 2027 | AW67: 2027 | AX67: 2027 | AY67: 2027 | AZ67: 2027 | BA67: 2027 | BB67: 2027 | BC67: 2027
B68: {=CONCATENATE("Model Running: ",INDEX(Inputs!$B$15:$B$17,Inputs!$D$8)," Drivers")} -> Model Running: Base Case Drivers | AF68: 1 | AG68: 1 | AH68: 1 | AI68: 2 | AJ68: 2 | AK68: 2 | AL68: 3 | AM68: 3 | AN68: 3 | AO68: 4 | AP68: 4 | AQ68: 4 | AR68: 1 | AS68: 1 | AT68: 1 | AU68: 2 | AV68: 2 | AW68: 2 | AX68: 3 | AY68: 3 | AZ68: 3 | BA68: 4 | BB68: 4 | BC68: 4
AF69: 46053 | AG69: 46081 | AH69: 46112 | AI69: 46142 | AJ69: 46173 | AK69: 46203 | AL69: 46234 | AM69: 46265 | AN69: 46295 | AO69: 46326 | AP69: 46356 | AQ69: 46387 | AR69: 46418 | AS69: 46446 | AT69: 46477 | AU69: 46507 | AV69: 46538 | AW69: 46568 | AX69: 46599 | AY69: 46630 | AZ69: 46660 | BA69: 46691 | BB69: 46721 | BC69: 46752
C71: Customer Bridge FY2026 | P71: Customer Bridge FY2027
AB72: Customer Growth & Retention
AB73: Gross Churn | AF73: =Inputs!F31 -> 0.02 | AG73: =Inputs!G31 -> 0.02 | AH73: =Inputs!H31 -> 0.02 | AI73: =Inputs!I31 -> 0.02 | AJ73: =Inputs!J31 -> 0.02 | AK73: =Inputs!K31 -> 0.02 | AL73: =Inputs!L31 -> 0.02 | AM73: =Inputs!M31 -> 0.02 | ... BC73: =Inputs!AC31 -> 0.018
AB74: ARPU | AF74: ='Operational Model'!G143 -> 1052.1 | AG74: ='Operational Model'!H143 -> 1054.2042 | AH74: ='Operational Model'!I143 -> 1056.3126 | AI74: ='Operational Model'!J143 -> 1058.4252 | AJ74: ='Operational Model'!K143 -> 1060.5421 | AK74: ='Operational Model'!L143 -> 1062.6632 | AL74: ='Operational Model'!M143 -> 1064.7885 | AM74: ='Operational Model'!N143 -> 1066.9181 | ... BC74: ='Operational Model'!AD143 -> 1114.8416
AB75: Beginning Customers | AF75: ='Operational Model'!G135 -> 850 | AG75: ='Operational Model'!H135 -> 868 | AH75: ='Operational Model'!I135 -> 885.6408 | AI75: ='Operational Model'!J135 -> 902.97158 | AJ75: ='Operational Model'!K135 -> 920.0401 | AK75: ='Operational Model'!L135 -> 936.89283 | AL75: ='Operational Model'!M135 -> 953.57498 | AM75: ='Operational Model'!N135 -> 970.13059 | ... BC75: ='Operational Model'!AD135 -> 1287.8472
AB76: New Customers | AF76: ='Operational Model'!G136 -> 35 | AG76: ='Operational Model'!H136 -> 35.0008 | AH76: ='Operational Model'!I136 -> 35.043592 | AI76: ='Operational Model'!J136 -> 35.127957 | AJ76: ='Operational Model'!K136 -> 35.253531 | AK76: ='Operational Model'!L136 -> 35.420002 | AL76: ='Operational Model'!M136 -> 35.627113 | AM76: ='Operational Model'!N136 -> 35.874657 | ... BC76: ='Operational Model'!AD136 -> 46.141196
AB77: Lost Customers | AF77: ='Operational Model'!G137 -> -17 | AG77: ='Operational Model'!H137 -> -17.36 | AH77: ='Operational Model'!I137 -> -17.712816 | AI77: ='Operational Model'!J137 -> -18.059432 | AJ77: ='Operational Model'!K137 -> -18.400802 | AK77: ='Operational Model'!L137 -> -18.737857 | AL77: ='Operational Model'!M137 -> -19.0715 | AM77: ='Operational Model'!N137 -> -19.402612 | ... BC77: ='Operational Model'!AD137 -> -23.18125
AB78: Ending Customers | AF78: ='Operational Model'!G138 -> 868 | AG78: ='Operational Model'!H138 -> 885.6408 | AH78: ='Operational Model'!I138 -> 902.97158 | AI78: ='Operational Model'!J138 -> 920.0401 | AJ78: ='Operational Model'!K138 -> 936.89283 | AK78: ='Operational Model'!L138 -> 953.57498 | AL78: ='Operational Model'!M138 -> 970.13059 | AM78: ='Operational Model'!N138 -> 986.60264 | ... BC78: ='Operational Model'!AD138 -> 1310.8072
AB79: Net Customer Adds | AF79: ='Operational Model'!G146 -> 18 | AG79: ='Operational Model'!H146 -> 17.6408 | AH79: ='Operational Model'!I146 -> 17.330776 | AI79: ='Operational Model'!J146 -> 17.068526 | AJ79: ='Operational Model'!K146 -> 16.852729 | AK79: ='Operational Model'!L146 -> 16.682146 | AL79: ='Operational Model'!M146 -> 16.555614 | AM79: ='Operational Model'!N146 -> 16.472045 | ... BC79: ='Operational Model'!AD146 -> 22.959946
AB80: Customer Growth | AF80: ='Operational Model'!G148 -> 0.021176471 | AG80: ='Operational Model'!H148 -> 0.020323502 | AH80: ='Operational Model'!I148 -> 0.019568629 | AI80: ='Operational Model'!J148 -> 0.018902617 | AJ80: ='Operational Model'!K148 -> 0.018317385 | AK80: ='Operational Model'!L148 -> 0.017805821 | AL80: ='Operational Model'!M148 -> 0.017361628 | AM80: ='Operational Model'!N148 -> 0.016979204 | ... BC80: ='Operational Model'!AD148 -> 0.01782816
AF84: FY2026 | AG84: FY2027
AB86: Beginning Customers | AF86: =AF75 -> 850 | AG86: =AR75 -> 1052.4803
AB87: New Customers | AF87: =SUM(AF76:AQ76) -> 429.12597 | AG87: =SUM(AR76:BC76) -> 510.69576
AB88: Lost Customers | AF88: =SUM(AF77:AQ77) -> -226.64563 | AG88: =SUM(AR77:BC77) -> -252.36893
AB89: Ending Customers | AF89: =AQ78 -> 1052.4803 | AG89: =BC78 -> 1310.8072
C99: Net Customer Adds | P99: ARPU & Gross Churn
B127: Operating Efficiency | AB127: Graphing Data
B129: All figures in EUR thousands unless stated | AB129: All figures in EUR thousands unless stated | AF129: 2026 | AG129: 2026 | AH129: 2026 | AI129: 2026 | AJ129: 2026 | AK129: 2026 | AL129: 2026 | AM129: 2026 | AN129: 2026 | AO129: 2026 | AP129: 2026 | AQ129: 2026 | AR129: 2027 | AS129: 2027 | AT129: 2027 | AU129: 2027 | AV129: 2027 | AW129: 2027 | AX129: 2027 | AY129: 2027 | AZ129: 2027 | BA129: 2027 | BB129: 2027 | BC129: 2027
B130: {=CONCATENATE("Model Running: ",INDEX(Inputs!$B$15:$B$17,Inputs!$D$8)," Drivers")} -> Model Running: Base Case Drivers | AF130: 1 | AG130: 1 | AH130: 1 | AI130: 2 | AJ130: 2 | AK130: 2 | AL130: 3 | AM130: 3 | AN130: 3 | AO130: 4 | AP130: 4 | AQ130: 4 | AR130: 1 | AS130: 1 | AT130: 1 | AU130: 2 | AV130: 2 | AW130: 2 | AX130: 3 | AY130: 3 | AZ130: 3 | BA130: 4 | BB130: 4 | BC130: 4
AF131: 46053 | AG131: 46081 | AH131: 46112 | AI131: 46142 | AJ131: 46173 | AK131: 46203 | AL131: 46234 | AM131: 46265 | AN131: 46295 | AO131: 46326 | AP131: 46356 | AQ131: 46387 | AR131: 46418 | AS131: 46446 | AT131: 46477 | AU131: 46507 | AV131: 46538 | AW131: 46568 | AX131: 46599 | AY131: 46630 | AZ131: 46660 | BA131: 46691 | BB131: 46721 | BC131: 46752
C133: Expenses | P133: EBITDA
AB134: Operating Efficiency
...

Sheet Inputs
B1: Gale Suer - Financial Analyst
B3: Scenario & Fixed Drivers
B5: All figures in EUR thousands unless stated
F7: =YEAR(F9) -> 2026 | G7: =YEAR(G9) -> 2026 | H7: =YEAR(H9) -> 2026 | I7: =YEAR(I9) -> 2026 | J7: =YEAR(J9) -> 2026 | K7: =YEAR(K9) -> 2026 | L7: =YEAR(L9) -> 2026 | M7: =YEAR(M9) -> 2026 | ... AC7: =YEAR(AC9) -> 2027
B8: Driver Switch | D8: 2 | F8: =CHOOSE(MONTH(F9),1,1,1,2,2,2,3,3,3,4,4,4) -> 1 | G8: =CHOOSE(MONTH(G9),1,1,1,2,2,2,3,3,3,4,4,4) -> 1 | H8: =CHOOSE(MONTH(H9),1,1,1,2,2,2,3,3,3,4,4,4) -> 1 | I8: =CHOOSE(MONTH(I9),1,1,1,2,2,2,3,3,3,4,4,4) -> 2 | J8: =CHOOSE(MONTH(J9),1,1,1,2,2,2,3,3,3,4,4,4) -> 2 | K8: =CHOOSE(MONTH(K9),1,1,1,2,2,2,3,3,3,4,4,4) -> 2 | L8: =CHOOSE(MONTH(L9),1,1,1,2,2,2,3,3,3,4,4,4) -> 3 | M8: =CHOOSE(MONTH(M9),1,1,1,2,2,2,3,3,3,4,4,4) -> 3 | ... AC8: =CHOOSE(MONTH(AC9),1,1,1,2,2,2,3,3,3,4,4,4) -> 4
F9: =E203 -> 46053 | G9: =EOMONTH(F9,1) -> 46081 | H9: =EOMONTH(G9,1) -> 46112 | I9: =EOMONTH(H9,1) -> 46142 | J9: =EOMONTH(I9,1) -> 46173 | K9: =EOMONTH(J9,1) -> 46203 | L9: =EOMONTH(K9,1) -> 46234 | M9: =EOMONTH(L9,1) -> 46265 | N9: =EOMONTH(M9,1) -> 46295 | ... AC9: =EOMONTH(AB9,1) -> 46752
B11: Revenue Drivers
B13: Lead Growth | F13: {=INDEX(F15:F17,$D$8)+'Operational Model'!$Q$547} -> 0.03 | G13: {=INDEX(G15:G17,$D$8)+'Operational Model'!$Q$547} -> 0.03 | H13: {=INDEX(H15:H17,$D$8)+'Operational Model'!$Q$547} -> 0.03 | I13: {=INDEX(I15:I17,$D$8)+'Operational Model'!$Q$547} -> 0.03 | J13: {=INDEX(J15:J17,$D$8)+'Operational Model'!$Q$547} -> 0.03 | K13: {=INDEX(K15:K17,$D$8)+'Operational Model'!$Q$547} -> 0.03 | L13: {=INDEX(L15:L17,$D$8)+'Operational Model'!$Q$547} -> 0.03 | M13: {=INDEX(M15:M17,$D$8)+'Operational Model'!$Q$547} -> 0.03 | ... AC13: {=INDEX(AC15:AC17,$D$8)+'Operational Model'!$Q$547} -> 0.025
B15: Best Case | F15: 0.05 | G15: 0.05 | H15: 0.05 | I15: 0.05 | J15: 0.05 | K15: 0.05 | L15: 0.05 | M15: 0.05 | N15: 0.05 | O15: 0.05 | P15: 0.05 | Q15: 0.05 | R15: 0.04 | S15: 0.04 | T15: 0.04 | U15: 0.04 | V15: 0.04 | W15: 0.04 | X15: 0.04 | Y15: 0.04 | Z15: 0.04 | AA15: 0.04 | AB15: 0.04 | AC15: 0.04
B16: Base Case | F16: 0.03 | G16: 0.03 | H16: 0.03 | I16: 0.03 | J16: 0.03 | K16: 0.03 | L16: 0.03 | M16: 0.03 | N16: 0.03 | O16: 0.03 | P16: 0.03 | Q16: 0.03 | R16: 0.025 | S16: 0.025 | T16: 0.025 | U16: 0.025 | V16: 0.025 | W16: 0.025 | X16: 0.025 | Y16: 0.025 | Z16: 0.025 | AA16: 0.025 | AB16: 0.025 | AC16: 0.025
B17: Worst Case | F17: 0.01 | G17: 0.01 | H17: 0.01 | I17: 0.01 | J17: 0.01 | K17: 0.01 | L17: 0.01 | M17: 0.01 | N17: 0.01 | O17: 0.01 | P17: 0.01 | Q17: 0.01 | R17: 0.005 | S17: 0.005 | T17: 0.005 | U17: 0.005 | V17: 0.005 | W17: 0.005 | X17: 0.005 | Y17: 0.005 | Z17: 0.005 | AA17: 0.005 | AB17: 0.005 | AC17: 0.005
B19: Conversion Rate | F19: {=INDEX(F21:F23,$D$8)+'Operational Model'!$Q$548} -> 0.04 | G19: {=INDEX(G21:G23,$D$8)+'Operational Model'!$Q$548} -> 0.04 | H19: {=INDEX(H21:H23,$D$8)+'Operational Model'!$Q$548} -> 0.04 | I19: {=INDEX(I21:I23,$D$8)+'Operational Model'!$Q$548} -> 0.04 | J19: {=INDEX(J21:J23,$D$8)+'Operational Model'!$Q$548} -> 0.04 | K19: {=INDEX(K21:K23,$D$8)+'Operational Model'!$Q$548} -> 0.04 | L19: {=INDEX(L21:L23,$D$8)+'Operational Model'!$Q$548} -> 0.04 | M19: {=INDEX(M21:M23,$D$8)+'Operational Model'!$Q$548} -> 0.04 | ... AC19: {=INDEX(AC21:AC23,$D$8)+'Operational Model'!$Q$548} -> 0.042
B21: =$B$15 -> Best Case | F21: 0.05 | G21: 0.05 | H21: 0.05 | I21: 0.05 | J21: 0.05 | K21: 0.05 | L21: 0.05 | M21: 0.05 | N21: 0.05 | O21: 0.05 | P21: 0.05 | Q21: 0.05 | R21: 0.055 | S21: 0.055 | T21: 0.055 | U21: 0.055 | V21: 0.055 | W21: 0.055 | X21: 0.055 | Y21: 0.055 | Z21: 0.055 | AA21: 0.055 | AB21: 0.055 | AC21: 0.055
B22: =$B$16 -> Base Case | F22: 0.04 | G22: 0.04 | H22: 0.04 | I22: 0.04 | J22: 0.04 | K22: 0.04 | L22: 0.04 | M22: 0.04 | N22: 0.04 | O22: 0.04 | P22: 0.04 | Q22: 0.04 | R22: 0.042 | S22: 0.042 | T22: 0.042 | U22: 0.042 | V22: 0.042 | W22: 0.042 | X22: 0.042 | Y22: 0.042 | Z22: 0.042 | AA22: 0.042 | AB22: 0.042 | AC22: 0.042
B23: =$B$17 -> Worst Case | F23: 0.03 | G23: 0.03 | H23: 0.03 | I23: 0.03 | J23: 0.03 | K23: 0.03 | L23: 0.03 | M23: 0.03 | N23: 0.03 | O23: 0.03 | P23: 0.03 | Q23: 0.03 | R23: 0.028 | S23: 0.028 | T23: 0.028 | U23: 0.028 | V23: 0.028 | W23: 0.028 | X23: 0.028 | Y23: 0.028 | Z23: 0.028 | AA23: 0.028 | AB23: 0.028 | AC23: 0.028
B25: ARPU Growth | F25: {=INDEX(F27:F29,$D$8)+'Operational Model'!$Q$549} -> 0.002 | G25: {=INDEX(G27:G29,$D$8)+'Operational Model'!$Q$549} -> 0.002 | H25: {=INDEX(H27:H29,$D$8)+'Operational Model'!$Q$549} -> 0.002 | I25: {=INDEX(I27:I29,$D$8)+'Operational Model'!$Q$549} -> 0.002 | J25: {=INDEX(J27:J29,$D$8)+'Operational Model'!$Q$549} -> 0.002 | K25: {=INDEX(K27:K29,$D$8)+'Operational Model'!$Q$549} -> 0.002 | L25: {=INDEX(L27:L29,$D$8)+'Operational Model'!$Q$549} -> 0.002 | M25: {=INDEX(M27:M29,$D$8)+'Operational Model'!$Q$549} -> 0.002 | ... AC25: {=INDEX(AC27:AC29,$D$8)+'Operational Model'!$Q$549} -> 0.003
B27: =$B$15 -> Best Case | F27: 0.004 | G27: 0.004 | H27: 0.004 | I27: 0.004 | J27: 0.004 | K27: 0.004 | L27: 0.004 | M27: 0.004 | N27: 0.004 | O27: 0.004 | P27: 0.004 | Q27: 0.004 | R27: 0.005 | S27: 0.005 | T27: 0.005 | U27: 0.005 | V27: 0.005 | W27: 0.005 | X27: 0.005 | Y27: 0.005 | Z27: 0.005 | AA27: 0.005 | AB27: 0.005 | AC27: 0.005
B28: =$B$16 -> Base Case | F28: 0.002 | G28: 0.002 | H28: 0.002 | I28: 0.002 | J28: 0.002 | K28: 0.002 | L28: 0.002 | M28: 0.002 | N28: 0.002 | O28: 0.002 | P28: 0.002 | Q28: 0.002 | R28: 0.003 | S28: 0.003 | T28: 0.003 | U28: 0.003 | V28: 0.003 | W28: 0.003 | X28: 0.003 | Y28: 0.003 | Z28: 0.003 | AA28: 0.003 | AB28: 0.003 | AC28: 0.003
B29: =$B$17 -> Worst Case | F29: 0 | G29: 0 | H29: 0 | I29: 0 | J29: 0 | K29: 0 | L29: 0 | M29: 0 | N29: 0 | O29: 0 | P29: 0 | Q29: 0 | R29: 0 | S29: 0 | T29: 0 | U29: 0 | V29: 0 | W29: 0 | X29: 0 | Y29: 0 | Z29: 0 | AA29: 0 | AB29: 0 | AC29: 0
B31: Gross Customer Churn | F31: {=INDEX(F33:F35,$D$8)+'Operational Model'!$Q$550} -> 0.02 | G31: {=INDEX(G33:G35,$D$8)+'Operational Model'!$Q$550} -> 0.02 | H31: {=INDEX(H33:H35,$D$8)+'Operational Model'!$Q$550} -> 0.02 | I31: {=INDEX(I33:I35,$D$8)+'Operational Model'!$Q$550} -> 0.02 | J31: {=INDEX(J33:J35,$D$8)+'Operational Model'!$Q$550} -> 0.02 | K31: {=INDEX(K33:K35,$D$8)+'Operational Model'!$Q$550} -> 0.02 | L31: {=INDEX(L33:L35,$D$8)+'Operational Model'!$Q$550} -> 0.02 | M31: {=INDEX(M33:M35,$D$8)+'Operational Model'!$Q$550} -> 0.02 | ... AC31: {=INDEX(AC33:AC35,$D$8)+'Operational Model'!$Q$550} -> 0.018
B33: =$B$15 -> Best Case | F33: 0.01 | G33: 0.01 | H33: 0.01 | I33: 0.01 | J33: 0.01 | K33: 0.01 | L33: 0.01 | M33: 0.01 | N33: 0.01 | O33: 0.01 | P33: 0.01 | Q33: 0.01 | R33: 0.008 | S33: 0.008 | T33: 0.008 | U33: 0.008 | V33: 0.008 | W33: 0.008 | X33: 0.008 | Y33: 0.008 | Z33: 0.008 | AA33: 0.008 | AB33: 0.008 | AC33: 0.008
B34: =$B$16 -> Base Case | F34: 0.02 | G34: 0.02 | H34: 0.02 | I34: 0.02 | J34: 0.02 | K34: 0.02 | L34: 0.02 | M34: 0.02 | N34: 0.02 | O34: 0.02 | P34: 0.02 | Q34: 0.02 | R34: 0.018 | S34: 0.018 | T34: 0.018 | U34: 0.018 | V34: 0.018 | W34: 0.018 | X34: 0.018 | Y34: 0.018 | Z34: 0.018 | AA34: 0.018 | AB34: 0.018 | AC34: 0.018
B35: =$B$17 -> Worst Case | F35: 0.035 | G35: 0.035 | H35: 0.035 | I35: 0.035 | J35: 0.035 | K35: 0.035 | L35: 0.035 | M35: 0.035 | N35: 0.035 | O35: 0.035 | P35: 0.035 | Q35: 0.035 | R35: 0.035 | S35: 0.035 | T35: 0.035 | U35: 0.035 | V35: 0.035 | W35: 0.035 | X35: 0.035 | Y35: 0.035 | Z35: 0.035 | AA35: 0.035 | AB35: 0.035 | AC35: 0.035
B37: Headcount Drivers
B39: Account Executive Hires | F39: {=INDEX(F41:F43,$D$8)} -> 0.7 | G39: {=INDEX(G41:G43,$D$8)} -> 0.7 | H39: {=INDEX(H41:H43,$D$8)} -> 0.7 | I39: {=INDEX(I41:I43,$D$8)} -> 0.7 | J39: {=INDEX(J41:J43,$D$8)} -> 0.7 | K39: {=INDEX(K41:K43,$D$8)} -> 0.7 | L39: {=INDEX(L41:L43,$D$8)} -> 0.7 | M39: {=INDEX(M41:M43,$D$8)} -> 0.7 | ... AC39: {=INDEX(AC41:AC43,$D$8)} -> 0.4
B41: =$B$15 -> Best Case | F41: 1.5 | G41: 1.5 | H41: 1.5 | I41: 1.5 | J41: 1.5 | K41: 1.5 | L41: 1.5 | M41: 1.5 | N41: 1.5 | O41: 1.5 | P41: 1.5 | Q41: 1.5 | R41: 1.1 | S41: 1.1 | T41: 1.1 | U41: 1.1 | V41: 1.1 | W41: 1.1 | X41: 1.1 | Y41: 1.1 | Z41: 1.1 | AA41: 1.1 | AB41: 1.1 | AC41: 1.1
B42: =$B$16 -> Base Case | F42: 0.7 | G42: 0.7 | H42: 0.7 | I42: 0.7 | J42: 0.7 | K42: 0.7 | L42: 0.7 | M42: 0.7 | N42: 0.7 | O42: 0.7 | P42: 0.7 | Q42: 0.7 | R42: 0.4 | S42: 0.4 | T42: 0.4 | U42: 0.4 | V42: 0.4 | W42: 0.4 | X42: 0.4 | Y42: 0.4 | Z42: 0.4 | AA42: 0.4 | AB42: 0.4 | AC42: 0.4
B43: =$B$17 -> Worst Case | F43: 0 | G43: 0 | H43: 0 | I43: 0 | J43: 0 | K43: 0 | L43: 0 | M43: 0 | N43: 0 | O43: 0 | P43: 0 | Q43: 0 | R43: 0 | S43: 0 | T43: 0 | U43: 0 | V43: 0 | W43: 0 | X43: 0 | Y43: 0 | Z43: 0 | AA43: 0 | AB43: 0 | AC43: 0
B45: Sales Development Rep Hires | F45: {=INDEX(F47:F49,$D$8)} -> 0.3 | G45: {=INDEX(G47:G49,$D$8)} -> 0.3 | H45: {=INDEX(H47:H49,$D$8)} -> 0.3 | I45: {=INDEX(I47:I49,$D$8)} -> 0.3 | J45: {=INDEX(J47:J49,$D$8)} -> 0.3 | K45: {=INDEX(K47:K49,$D$8)} -> 0.3 | L45: {=INDEX(L47:L49,$D$8)} -> 0.3 | M45: {=INDEX(M47:M49,$D$8)} -> 0.3 | ... AC45: {=INDEX(AC47:AC49,$D$8)} -> 0.1
B47: =$B$15 -> Best Case | F47: 0.5 | G47: 0.5 | H47: 0.5 | I47: 0.5 | J47: 0.5 | K47: 0.5 | L47: 0.5 | M47: 0.5 | N47: 0.5 | O47: 0.5 | P47: 0.5 | Q47: 0.5 | R47: 0.4 | S47: 0.4 | T47: 0.4 | U47: 0.4 | V47: 0.4 | W47: 0.4 | X47: 0.4 | Y47: 0.4 | Z47: 0.4 | AA47: 0.4 | AB47: 0.4 | AC47: 0.4
B48: =$B$16 -> Base Case | F48: 0.3 | G48: 0.3 | H48: 0.3 | I48: 0.3 | J48: 0.3 | K48: 0.3 | L48: 0.3 | M48: 0.3 | N48: 0.3 | O48: 0.3 | P48: 0.3 | Q48: 0.3 | R48: 0.1 | S48: 0.1 | T48: 0.1 | U48: 0.1 | V48: 0.1 | W48: 0.1 | X48: 0.1 | Y48: 0.1 | Z48: 0.1 | AA48: 0.1 | AB48: 0.1 | AC48: 0.1
B49: =$B$17 -> Worst Case | F49: 0 | G49: 0 | H49: 0 | I49: 0 | J49: 0 | K49: 0 | L49: 0 | M49: 0 | N49: 0 | O49: 0 | P49: 0 | Q49: 0 | R49: 0 | S49: 0 | T49: 0 | U49: 0 | V49: 0 | W49: 0 | X49: 0 | Y49: 0 | Z49: 0 | AA49: 0 | AB49: 0 | AC49: 0
B51: Customer Succes Hires | F51: {=INDEX(F53:F55,$D$8)} -> 0.5 | G51: {=INDEX(G53:G55,$D$8)} -> 0.5 | H51: {=INDEX(H53:H55,$D$8)} -> 0.5 | I51: {=INDEX(I53:I55,$D$8)} -> 0.5 | J51: {=INDEX(J53:J55,$D$8)} -> 0.5 | K51: {=INDEX(K53:K55,$D$8)} -> 0.5 | L51: {=INDEX(L53:L55,$D$8)} -> 0.5 | M51: {=INDEX(M53:M55,$D$8)} -> 0.5 | ... AC51: {=INDEX(AC53:AC55,$D$8)} -> 0.3
B53: =$B$15 -> Best Case | F53: 1 | G53: 1 | H53: 1 | I53: 1 | J53: 1 | K53: 1 | L53: 1 | M53: 1 | N53: 1 | O53: 1 | P53: 1 | Q53: 1 | R53: 1 | S53: 1 | T53: 1 | U53: 1 | V53: 1 | W53: 1 | X53: 1 | Y53: 1 | Z53: 1 | AA53: 1 | AB53: 1 | AC53: 1
B54: =$B$16 -> Base Case | F54: 0.5 | G54: 0.5 | H54: 0.5 | I54: 0.5 | J54: 0.5 | K54: 0.5 | L54: 0.5 | M54: 0.5 | N54: 0.5 | O54: 0.5 | P54: 0.5 | Q54: 0.5 | R54: 0.25 | S54: 0.3 | T54: 0.3 | U54: 0.3 | V54: 0.3 | W54: 0.3 | X54: 0.3 | Y54: 0.3 | Z54: 0.3 | AA54: 0.3 | AB54: 0.3 | AC54: 0.3
B55: =$B$17 -> Worst Case | F55: 0 | G55: 0 | H55: 0 | I55: 0 | J55: 0 | K55: 0 | L55: 0 | M55: 0 | N55: 0 | O55: 0 | P55: 0 | Q55: 0 | R55: 0 | S55: 0 | T55: 0 | U55: 0 | V55: 0 | W55: 0 | X55: 0 | Y55: 0 | Z55: 0 | AA55: 0 | AB55: 0 | AC55: 0
B57: Product Hires | F57: {=INDEX(F59:F61,$D$8)} -> 1 | G57: {=INDEX(G59:G61,$D$8)} -> 1 | H57: {=INDEX(H59:H61,$D$8)} -> 1 | I57: {=INDEX(I59:I61,$D$8)} -> 1 | J57: {=INDEX(J59:J61,$D$8)} -> 1 | K57: {=INDEX(K59:K61,$D$8)} -> 1 | L57: {=INDEX(L59:L61,$D$8)} -> 1 | M57: {=INDEX(M59:M61,$D$8)} -> 1 | ... AC57: {=INDEX(AC59:AC61,$D$8)} -> 0.5
B59: =$B$15 -> Best Case | F59: 2 | G59: 2 | H59: 2 | I59: 2 | J59: 2 | K59: 2 | L59: 2 | M59: 2 | N59: 2 | O59: 2 | P59: 2 | Q59: 2 | R59: 1.5 | S59: 1.5 | T59: 1.5 | U59: 1.5 | V59: 1.5 | W59: 1.5 | X59: 1.5 | Y59: 1.5 | Z59: 1.5 | AA59: 1.5 | AB59: 1.5 | AC59: 1.5
B60: =$B$16 -> Base Case | F60: 1 | G60: 1 | H60: 1 | I60: 1 | J60: 1 | K60: 1 | L60: 1 | M60: 1 | N60: 1 | O60: 1 | P60: 1 | Q60: 1 | R60: 0.5 | S60: 0.5 | T60: 0.5 | U60: 0.5 | V60: 0.5 | W60: 0.5 | X60: 0.5 | Y60: 0.5 | Z60: 0.5 | AA60: 0.5 | AB60: 0.5 | AC60: 0.5
B61: =$B$17 -> Worst Case | F61: 0 | G61: 0 | H61: 0 | I61: 0 | J61: 0 | K61: 0 | L61: 0 | M61: 0 | N61: 0 | O61: 0 | P61: 0 | Q61: 0 | R61: 0 | S61: 0 | T61: 0 | U61: 0 | V61: 0 | W61: 0 | X61: 0 | Y61: 0 | Z61: 0 | AA61: 0 | AB61: 0 | AC61: 0
...

Sheet Operational Model
B1: Gale Suer - Financial Analyst
B3: Income Statement
B5: All figures in EUR thousands unless stated | G5: =Inputs!F$7 -> 2026 | H5: =Inputs!G$7 -> 2026 | I5: =Inputs!H$7 -> 2026 | J5: =Inputs!I$7 -> 2026 | K5: =Inputs!J$7 -> 2026 | L5: =Inputs!K$7 -> 2026 | M5: =Inputs!L$7 -> 2026 | N5: =Inputs!M$7 -> 2026 | ... AD5: =Inputs!AC$7 -> 2027
B6: {=CONCATENATE("Model Running: ",INDEX(Inputs!$B$15:$B$17,Inputs!$D$8)," Drivers")} -> Model Running: Base Case Drivers | G6: =Inputs!F$8 -> 1 | H6: =Inputs!G$8 -> 1 | I6: =Inputs!H$8 -> 1 | J6: =Inputs!I$8 -> 2 | K6: =Inputs!J$8 -> 2 | L6: =Inputs!K$8 -> 2 | M6: =Inputs!L$8 -> 3 | N6: =Inputs!M$8 -> 3 | ... AD6: =Inputs!AC$8 -> 4
G7: =Inputs!F$9 -> 46053 | H7: =Inputs!G$9 -> 46081 | I7: =Inputs!H$9 -> 46112 | J7: =Inputs!I$9 -> 46142 | K7: =Inputs!J$9 -> 46173 | L7: =Inputs!K$9 -> 46203 | M7: =Inputs!L$9 -> 46234 | N7: =Inputs!M$9 -> 46265 | ... AD7: =Inputs!AC$9 -> 46752
B10: Revenue | G10: =G155 -> 913.2228 | H10: =H155 -> 933.64625 | I10: =I155 -> 953.82026 | J10: =J155 -> 973.79366 | K10: =K155 -> 993.61427 | L10: =L155 -> 1013.329 | M10: =M155 -> 1032.9839 | N10: =N155 -> 1052.6242 | ... AD10: =AD155 -> 1461.3423
B11: Cost of Revenue
B12: Customer Succes Personnel | G12: =-G279 -> -89.924167 | H12: =-H279 -> -92.8725 | I12: =-I279 -> -95.820833 | J12: =-J279 -> -98.769167 | K12: =-K279 -> -101.7175 | L12: =-L279 -> -104.66583 | M12: =-M279 -> -107.61417 | N12: =-N279 -> -110.5625 | ... AD12: =-AD279 -> -143.87867
B13: Hosting & Infrastructure | G13: =-G280 -> -45.66114 | H13: =-H280 -> -46.682313 | I13: =-I280 -> -47.691013 | J13: =-J280 -> -48.689683 | K13: =-K280 -> -49.680714 | L13: =-L280 -> -50.66645 | M13: =-M280 -> -51.649195 | N13: =-N280 -> -52.631209 | ... AD13: =-AD280 -> -73.067116
B14: Gross Profit | G14: =SUM(G10:G13) -> 777.63749 | H14: =SUM(H10:H13) -> 794.09144 | I14: =SUM(I10:I13) -> 810.30841 | J14: =SUM(J10:J13) -> 826.33481 | K14: =SUM(K10:K13) -> 842.21606 | L14: =SUM(L10:L13) -> 857.99672 | M14: =SUM(M10:M13) -> 873.72053 | N14: =SUM(N10:N13) -> 889.43047 | ... AD14: =SUM(AD10:AD13) -> 1244.3965
B16: Gross Margin | G16: =MAX(G14/G10,0) -> 0.85153097 | H16: =MAX(H14/H10,0) -> 0.8505271 | I16: =MAX(I14/I10,0) -> 0.84953995 | J16: =MAX(J14/J10,0) -> 0.8485728 | K16: =MAX(K14/K10,0) -> 0.84762879 | L16: =MAX(L14/L10,0) -> 0.84671091 | M16: =MAX(M14/M10,0) -> 0.84582203 | N16: =MAX(N14/N10,0) -> 0.84496489 | ... AD16: =MAX(AD14/AD10,0) -> 0.85154349
B19: Sales & Marketing | G19: =-G302 -> -309.96161 | H19: =-H302 -> -319.17506 | I19: =-I302 -> -328.35359 | J19: =-J302 -> -337.50403 | K19: =-K302 -> -346.63308 | L19: =-L302 -> -355.74731 | M19: =-M302 -> -364.85316 | N19: =-N302 -> -373.95697 | ... AD19: =-AD302 -> -483.15575
B20: R&D / Product | G20: =-G250 -> -306.77917 | H20: =-H250 -> -315.42083 | I20: =-I250 -> -324.0625 | J20: =-J250 -> -332.70417 | K20: =-K250 -> -341.34583 | L20: =-L250 -> -349.9875 | M20: =-M250 -> -358.62917 | N20: =-N250 -> -367.27083 | ... AD20: =-AD250 -> -455.84792
B21: G&A | G21: =-G303 -> -204.6552 | H21: =-H303 -> -208.68004 | I21: =-I303 -> -212.67994 | J21: =-J303 -> -216.65978 | K21: =-K303 -> -220.62434 | L21: =-L303 -> -224.57832 | M21: =-M303 -> -228.52631 | N21: =-N303 -> -232.47283 | ... AD21: =-AD303 -> -275.25206
B22: EBITDA | G22: =G14+SUM(G19:G21) -> -43.758479 | H22: =H14+SUM(H19:H21) -> -49.184495 | I22: =I14+SUM(I19:I21) -> -54.787615 | J22: =J14+SUM(J19:J21) -> -60.533169 | K22: =K14+SUM(K19:K21) -> -66.387198 | L22: =L14+SUM(L19:L21) -> -72.316406 | M22: =M14+SUM(M19:M21) -> -78.288105 | N22: =N14+SUM(N19:N21) -> -84.270165 | ... AD22: =AD14+SUM(AD19:AD21) -> 30.140804
B24: EBITDA Margin | G24: =G22/G10 -> -0.047916542 | H24: =H22/H10 -> -0.052680011 | I24: =I22/I10 -> -0.057440188 | J24: =J22/J10 -> -0.062162213 | K24: =K22/K10 -> -0.066813853 | L24: =L22/L10 -> -0.07136518 | M24: =M22/M10 -> -0.075788311 | N24: =N22/N10 -> -0.080057219 | ... AD24: =AD22/AD10 -> 0.020625423
B27: Depreciation | G27: =-G451 -> -15.785124 | H27: =-H451 -> -16.303816 | I27: =-I451 -> -16.833716 | J27: =-J451 -> -17.374713 | K27: =-K451 -> -17.926721 | L27: =-L451 -> -18.489681 | M27: =-M451 -> -19.063561 | N27: =-N451 -> -19.648352 | ... AD27: =-AD451 -> -29.932065
B28: EBIT | G28: =G22+G27 -> -59.543602 | H28: =H22+H27 -> -65.488311 | I28: =I22+I27 -> -71.621331 | J28: =J22+J27 -> -77.907881 | K28: =K22+K27 -> -84.313919 | L28: =L22+L27 -> -90.806088 | M28: =M22+M27 -> -97.351666 | N28: =N22+N27 -> -103.91852 | ... AD28: =AD22+AD27 -> 0.2087393
B31: Interest Income | G31: =G329*Inputs!$E$210/12 -> 8.0208333 | H31: =H329*Inputs!$E$210/12 -> 8.029714 | I31: =I329*Inputs!$E$210/12 -> 8.0218887 | J31: =J329*Inputs!$E$210/12 -> 8.000132 | K31: =K329*Inputs!$E$210/12 -> 7.9644008 | L31: =L329*Inputs!$E$210/12 -> 7.9147151 | M31: =M329*Inputs!$E$210/12 -> 7.851157 | N31: =N329*Inputs!$E$210/12 -> 7.7738703 | ... AD31: =AD329*Inputs!$E$210/12 -> 7.4299032
B32: EBT | G32: =G28+G31 -> -51.522769 | H32: =H28+H31 -> -57.458597 | I32: =I28+I31 -> -63.599442 | J32: =J28+J31 -> -69.907749 | K32: =K28+K31 -> -76.349518 | L32: =L28+L31 -> -82.891373 | M32: =M28+M31 -> -89.500509 | N32: =N28+N31 -> -96.144647 | ... AD32: =AD28+AD31 -> 7.6386425
B35: Current Tax | G35: =-MAX(G32*Inputs!$E$209,0) -> 0 | H35: =-MAX(H32*Inputs!$E$209,0) -> 0 | I35: =-MAX(I32*Inputs!$E$209,0) -> 0 | J35: =-MAX(J32*Inputs!$E$209,0) -> 0 | K35: =-MAX(K32*Inputs!$E$209,0) -> 0 | L35: =-MAX(L32*Inputs!$E$209,0) -> 0 | M35: =-MAX(M32*Inputs!$E$209,0) -> 0 | N35: =-MAX(N32*Inputs!$E$209,0) -> 0 | ... AD35: =-MAX(AD32*Inputs!$E$209,0) -> -1.9707698
B38: Net Income | G38: =G32+G35 -> -51.522769 | H38: =H32+H35 -> -57.458597 | I38: =I32+I35 -> -63.599442 | J38: =J32+J35 -> -69.907749 | K38: =K32+K35 -> -76.349518 | L38: =L32+L35 -> -82.891373 | M38: =M32+M35 -> -89.500509 | N38: =N32+N35 -> -96.144647 | ... AD38: =AD32+AD35 -> 5.6678728
B42: Cash Flow Statement
B44: All figures in EUR thousands unless stated | G44: =G$5 -> 2026 | H44: =H$5 -> 2026 | I44: =I$5 -> 2026 | J44: =J$5 -> 2026 | K44: =K$5 -> 2026 | L44: =L$5 -> 2026 | M44: =M$5 -> 2026 | N44: =N$5 -> 2026 | ... AD44: =AD$5 -> 2027
B45: {=CONCATENATE("Model Running: ",INDEX(Inputs!$B$15:$B$17,Inputs!$D$8)," Drivers")} -> Model Running: Base Case Drivers | G45: =G$6 -> 1 | H45: =H$6 -> 1 | I45: =I$6 -> 1 | J45: =J$6 -> 2 | K45: =K$6 -> 2 | L45: =L$6 -> 2 | M45: =M$6 -> 3 | N45: =N$6 -> 3 | ... AD45: =AD$6 -> 4
G46: =G$7 -> 46053 | H46: =H$7 -> 46081 | I46: =I$7 -> 46112 | J46: =J$7 -> 46142 | K46: =K$7 -> 46173 | L46: =L$7 -> 46203 | M46: =M$7 -> 46234 | N46: =N$7 -> 46265 | ... AD46: =AD$7 -> 46752
B49: Cash From Operating Activities
B50: Net Income | G50: =G38 -> -51.522769 | H50: =H38 -> -57.458597 | I50: =I38 -> -63.599442 | J50: =J38 -> -69.907749 | K50: =K38 -> -76.349518 | L50: =L38 -> -82.891373 | M50: =M38 -> -89.500509 | N50: =N38 -> -96.144647 | ... AD50: =AD38 -> 5.6678728
B51: Depreciation | G51: =-G27 -> 15.785124 | H51: =-H27 -> 16.303816 | I51: =-I27 -> 16.833716 | J51: =-J27 -> 17.374713 | K51: =-K27 -> 17.926721 | L51: =-L27 -> 18.489681 | M51: =-M27 -> 19.063561 | N51: =-N27 -> 19.648352 | ... AD51: =-AD27 -> 29.932065
B52: Changes in Working Capital
B53: Change in Accounts Receivable | G53: =-G387 -> -21.66356 | H53: =-H387 -> -21.104233 | I53: =-I387 -> -20.846477 | J53: =-J387 -> -20.639179 | K53: =-K387 -> -20.481303 | L53: =-L387 -> -20.371888 | M53: =-M387 -> -20.310048 | N53: =-N387 -> -20.294967 | ... AD53: =-AD387 -> -30.887425
B54: Change in Accounts Payable | G54: =G388 -> 12.251918 | H54: =H388 -> 8.8842012 | I54: =I388 -> 8.7756942 | J54: =J388 -> 8.6884284 | K54: =K388 -> 8.6219677 | L54: =L388 -> 8.5759077 | M54: =M388 -> 8.549875 | N54: =N388 -> 8.5435265 | ... AD54: =AD388 -> 12.105878
B55: Change in Accrued Expenses | G55: =G389 -> 0.60733333 | H55: =H389 -> 0.99633333 | I55: =I389 -> 0.99633333 | J55: =J389 -> 0.99633333 | K55: =K389 -> 0.99633333 | L55: =L389 -> 0.99633333 | M55: =M389 -> 0.99633333 | N55: =N389 -> 0.99633333 | ... AD55: =AD389 -> 0.50274167
B56: Change in Prepaid Expenses | G56: =-G390 -> 0.433886 | H56: =-H390 -> -0.10211726 | I56: =-I390 -> -0.10087005 | J56: =-J390 -> -0.099866993 | K56: =-K390 -> -0.099103077 | L56: =-L390 -> -0.098573651 | M56: =-M390 -> -0.098274425 | N56: =-N390 -> -0.098201454 | ... AD56: =-AD390 -> -0.13450975
B57: Change in Deferred Revenue | G57: =G414 -> 66.63524 | H57: =H414 -> 67.397388 | I57: =I414 -> 66.574232 | J57: =J414 -> 65.912215 | K57: =K414 -> 65.408031 | L57: =L414 -> 65.05861 | M57: =M414 -> 64.861121 | N57: =N414 -> 64.812959 | ... AD57: =AD414 -> 98.640486
B58: Subtotal | G58: =SUM(G50:G57) -> 22.527172 | H58: =SUM(H50:H57) -> 14.916792 | I58: =SUM(I50:I57) -> 8.6331867 | J58: =SUM(J50:J57) -> 2.3248952 | K58: =SUM(K50:K57) -> -3.9768714 | L58: =SUM(L50:L57) -> -10.241302 | M58: =SUM(M50:M57) -> -16.437941 | N58: =SUM(N50:N57) -> -22.536644 | ... AD58: =SUM(AD50:AD57) -> 115.82711
B61: Cash From Investing Activities
B62: Capital Expenditure | G62: =-G441 -> -18.264456 | H62: =-H441 -> -18.672925 | I62: =-I441 -> -19.076405 | J62: =-J441 -> -19.475873 | K62: =-K441 -> -19.872285 | L62: =-L441 -> -20.26658 | M62: =-M441 -> -20.659678 | N62: =-N441 -> -21.052484 | ... AD62: =-AD441 -> -26.304162
B63: Subtotal | G63: =G62 -> -18.264456 | H63: =H62 -> -18.672925 | I63: =I62 -> -19.076405 | J63: =J62 -> -19.475873 | K63: =K62 -> -19.872285 | L63: =L62 -> -20.26658 | M63: =M62 -> -20.659678 | N63: =N62 -> -21.052484 | ... AD63: =AD62 -> -26.304162
B66: Cash From Financing
...

Sheet Valuation
B1: Gale Suer - Financial Analyst
B3: Long Term Financial Forecast
B5: All figures in EUR thousands unless stated
B6: {=CONCATENATE("Model Running: ",INDEX(Inputs!$B$15:$B$17,Inputs!$D$8)," Drivers")} -> Model Running: Base Case Drivers
I7: 2026 | J7: =I7+1 -> 2027 | K7: =J7+1 -> 2028 | L7: =K7+1 -> 2029 | M7: =L7+1 -> 2030 | N7: =M7+1 -> 2031 | O7: =N7+1 -> 2032 | P7: =O7+1 -> 2033 | Q7: =P7+1 -> 2034 | R7: =Q7+1 -> 2035 | S7: Term.
B10: Revenue | I10: =IF(I55<>0,I55,H10*(1+Inputs!D133)) -> 12275.187 | J10: =IF(J55<>0,J55,I10*(1+Inputs!E133)) -> 15669.477 | K10: =IF(K55<>0,K55,J10*(1+Inputs!F133)) -> 19273.456 | L10: =IF(L55<>0,L55,K10*(1+Inputs!G133)) -> 22935.413 | M10: =IF(M55<>0,M55,L10*(1+Inputs!H133)) -> 26605.079 | N10: =IF(N55<>0,N55,M10*(1+Inputs!I133)) -> 30063.739 | O10: =IF(O55<>0,O55,N10*(1+Inputs!J133)) -> 33070.113 | P10: =IF(P55<>0,P55,O10*(1+Inputs!K133)) -> 35715.722 | ... S10: =IF(S55<>0,S55,R10*(1+Inputs!N133)) -> 40357.337
B11: Cost of Revenue | I11: =I12-I10 -> -1887.4394 | J11: =J12-J10 -> -2393.4112 | K11: =K12-K10 -> -2794.6511 | L11: =L12-L10 -> -3210.9578 | M11: =M12-M10 -> -3591.6857 | N11: =N12-N10 -> -3908.2861 | O11: =O12-O10 -> -4299.1147 | P11: =P12-P10 -> -4643.0439 | ... S11: =S12-S10 -> -5246.4539
B12: Gross Profit | I12: =IF(I57<>0,I57,I10*Inputs!D139) -> 10387.748 | J12: =IF(J57<>0,J57,J10*Inputs!E139) -> 13276.065 | K12: =IF(K57<>0,K57,K10*Inputs!F139) -> 16478.805 | L12: =IF(L57<>0,L57,L10*Inputs!G139) -> 19724.455 | M12: =IF(M57<>0,M57,M10*Inputs!H139) -> 23013.393 | N12: =IF(N57<>0,N57,N10*Inputs!I139) -> 26155.453 | O12: =IF(O57<>0,O57,O10*Inputs!J139) -> 28770.998 | P12: =IF(P57<>0,P57,P10*Inputs!K139) -> 31072.678 | ... S12: =IF(S57<>0,S57,S10*Inputs!N139) -> 35110.884
B14: Gross Margin | I14: =I12/I10 -> 0.84623947 | J14: =J12/J10 -> 0.84725646 | K14: =K12/K10 -> 0.855 | L14: =L12/L10 -> 0.86 | M14: =M12/M10 -> 0.865 | N14: =N12/N10 -> 0.87 | O14: =O12/O10 -> 0.87 | P14: =P12/P10 -> 0.87 | ... S14: =S12/S10 -> 0.87
B16: OpEx (Sales & Marketing + R&D/Product + G&A) | I16: =I17-I12 -> -11293.285 | J16: =J17-J12 -> -13724.058 | K16: =K17-K12 -> -15515.132 | L16: =L17-L12 -> -17889.622 | M16: =M17-M12 -> -20086.835 | N16: =N17-N12 -> -21946.53 | O16: =O17-O12 -> -23314.43 | P16: =P17-P12 -> -24465.27 | ... S16: =S17-S12 -> -26232.269
B17: EBITDA | I17: =IF(I62<>0,I62,I10*Inputs!D145) -> -905.53701 | J17: =IF(J62<>0,J62,J10*Inputs!E145) -> -447.99229 | K17: =IF(K62<>0,K62,K10*Inputs!F145) -> 963.67281 | L17: =IF(L62<>0,L62,L10*Inputs!G145) -> 1834.833 | M17: =IF(M62<>0,M62,M10*Inputs!H145) -> 2926.5587 | N17: =IF(N62<>0,N62,N10*Inputs!I145) -> 4208.9235 | O17: =IF(O62<>0,O62,O10*Inputs!J145) -> 5456.5687 | P17: =IF(P62<>0,P62,P10*Inputs!K145) -> 6607.4086 | ... S17: =IF(S62<>0,S62,S10*Inputs!N145) -> 8878.6142
B19: EBITDA Margin | I19: =I17/I10 -> -0.07376971 | J19: =J17/J10 -> -0.028590125 | K19: =K17/K10 -> 0.05 | L19: =L17/L10 -> 0.08 | M19: =M17/M10 -> 0.11 | N19: =N17/N10 -> 0.14 | O19: =O17/O10 -> 0.165 | P19: =P17/P10 -> 0.185 | ... S19: =S17/S10 -> 0.22
B21: Depreciation | I21: =IF(I66<>0,I66,-I10*Inputs!D151) -> -226.08632 | J21: =IF(J66<>0,J66,-J10*Inputs!E151) -> -314.12326 | K21: =IF(K66<>0,K66,-K10*Inputs!F151) -> -385.46912 | L21: =IF(L66<>0,L66,-L10*Inputs!G151) -> -435.77284 | M21: =IF(M66<>0,M66,-M10*Inputs!H151) -> -505.4965 | N21: =IF(N66<>0,N66,-N10*Inputs!I151) -> -541.14731 | O21: =IF(O66<>0,O66,-O10*Inputs!J151) -> -595.26204 | P21: =IF(P66<>0,P66,-P10*Inputs!K151) -> -642.883 | ... S21: =IF(S66<>0,S66,-S10*Inputs!N151) -> -726.43207
B22: EBIT | I22: =I17+I21 -> -1131.6233 | J22: =J17+J21 -> -762.11555 | K22: =K17+K21 -> 578.20369 | L22: =L17+L21 -> 1399.0602 | M22: =M17+M21 -> 2421.0622 | N22: =N17+N21 -> 3667.7762 | O22: =O17+O21 -> 4861.3066 | P22: =P17+P21 -> 5964.5256 | ... S22: =S17+S21 -> 8152.1822
B24: EBIT Margin | I24: =I22/I10 -> -0.092187867 | J24: =J22/J10 -> -0.04863695 | K24: =K22/K10 -> 0.03 | L24: =L22/L10 -> 0.061 | M24: =M22/M10 -> 0.091 | N24: =N22/N10 -> 0.122 | O24: =O22/O10 -> 0.147 | P24: =P22/P10 -> 0.167 | ... S24: =S22/S10 -> 0.202
B28: Unlevered Free Cash Flow Schedule
B30: All figures in EUR thousands unless stated
B31: {=CONCATENATE("Model Running: ",INDEX(Inputs!$B$15:$B$17,Inputs!$D$8)," Drivers")} -> Model Running: Base Case Drivers
I32: 2026 | J32: =I32+1 -> 2027 | K32: =J32+1 -> 2028 | L32: =K32+1 -> 2029 | M32: =L32+1 -> 2030 | N32: =M32+1 -> 2031 | O32: =N32+1 -> 2032 | P32: =O32+1 -> 2033 | Q32: =P32+1 -> 2034 | R32: =Q32+1 -> 2035 | S32: Term.
B34: Net Working Capital
B35: Ending Net Working Capital | I35: =IF(I77<>0,I77,I10*Inputs!D163) -> -3097.9795 | J35: =IF(J77<>0,J77,J10*Inputs!E163) -> -3949.4755 | K35: =IF(K77<>0,K77,K10*Inputs!F163) -> -4818.364 | L35: =IF(L77<>0,L77,L10*Inputs!G163) -> -5733.8532 | M35: =IF(M77<>0,M77,M10*Inputs!H163) -> -6651.2697 | N35: =IF(N77<>0,N77,N10*Inputs!I163) -> -7515.9348 | O35: =IF(O77<>0,O77,O10*Inputs!J163) -> -8267.5283 | P35: =IF(P77<>0,P77,P10*Inputs!K163) -> -8928.9305 | ... S35: =IF(S77<>0,S77,S10*Inputs!N163) -> -10089.334
B36: Change in Net Working Capital | I36: =IF(I80<>0,I80,I35-H35) -> -658.97945 | J36: =IF(J80<>0,J80,J35-I35) -> -851.496 | K36: =IF(K80<>0,K80,K35-J35) -> -868.88859 | L36: =IF(L80<>0,L80,L35-K35) -> -915.48917 | M36: =IF(M80<>0,M80,M35-L35) -> -917.41651 | N36: =IF(N80<>0,N80,N35-M35) -> -864.66506 | O36: =IF(O80<>0,O80,O35-N35) -> -751.59348 | P36: =IF(P80<>0,P80,P35-O35) -> -661.40226 | ... S36: =IF(S80<>0,S80,S35-R35) -> -246.08133
B38: EBITDA Method
B39: EBITDA | I39: =I17 -> -905.53701 | J39: =J17 -> -447.99229 | K39: =K17 -> 963.67281 | L39: =L17 -> 1834.833 | M39: =M17 -> 2926.5587 | N39: =N17 -> 4208.9235 | O39: =O17 -> 5456.5687 | P39: =P17 -> 6607.4086 | ... S39: =S17 -> 8878.6142
B40: Current Tax | I40: =-MAX(I22*Inputs!$E$209,0) -> 0 | J40: =-MAX(J22*Inputs!$E$209,0) -> 0 | K40: =-MAX(K22*Inputs!$E$209,0) -> -149.17655 | L40: =-MAX(L22*Inputs!$E$209,0) -> -360.95753 | M40: =-MAX(M22*Inputs!$E$209,0) -> -624.63404 | N40: =-MAX(N22*Inputs!$E$209,0) -> -946.28625 | O40: =-MAX(O22*Inputs!$E$209,0) -> -1254.2171 | P40: =-MAX(P22*Inputs!$E$209,0) -> -1538.8476 | ... S40: =-MAX(S22*Inputs!$E$209,0) -> -2103.263
B41: Capital Expenditure | I41: =IF(I73<>0,I73,-I10*Inputs!D157) -> -245.50375 | J41: =IF(J73<>0,J73,-J10*Inputs!E157) -> -282.05058 | K41: =IF(K73<>0,K73,-K10*Inputs!F157) -> -346.92221 | L41: =IF(L73<>0,L73,-L10*Inputs!G157) -> -412.83743 | M41: =IF(M73<>0,M73,-M10*Inputs!H157) -> -478.89142 | N41: =IF(N73<>0,N73,-N10*Inputs!I157) -> -541.14731 | O41: =IF(O73<>0,O73,-O10*Inputs!J157) -> -595.26204 | P41: =IF(P73<>0,P73,-P10*Inputs!K157) -> -642.883 | ... S41: =IF(S73<>0,S73,-S10*Inputs!N157) -> -726.43207
B42: (-) Change in NWC | I42: =-I36 -> 658.97945 | J42: =-J36 -> 851.496 | K42: =-K36 -> 868.88859 | L42: =-L36 -> 915.48917 | M42: =-M36 -> 917.41651 | N42: =-N36 -> 864.66506 | O42: =-O36 -> 751.59348 | P42: =-P36 -> 661.40226 | ... S42: =-S36 -> 246.08133
B43: Unlevered Free Cash Flow | I43: =SUM(I39:I42) -> -492.0613 | J43: =SUM(J39:J42) -> 121.45313 | K43: =SUM(K39:K42) -> 1336.4626 | L43: =SUM(L39:L42) -> 1976.5272 | M43: =SUM(M39:M42) -> 2740.4497 | N43: =SUM(N39:N42) -> 3586.155 | O43: =SUM(O39:O42) -> 4358.683 | P43: =SUM(P39:P42) -> 5087.0803 | ... S43: =SUM(S39:S42) -> 6295.0005
B47: Operational Data Schedule
B49: All figures in EUR thousands unless stated
B50: {=CONCATENATE("Model Running: ",INDEX(Inputs!$B$15:$B$17,Inputs!$D$8)," Drivers")} -> Model Running: Base Case Drivers
I51: =I7 -> 2026 | J51: =J7 -> 2027
B53: Financial Forecast
B55: Revenue | I55: =SUM('Operational Model'!G10:R10) -> 12275.187 | J55: =SUM('Operational Model'!S10:AD10) -> 15669.477
B56: Cost of Revenue | I56: =SUM('Operational Model'!G12:R13) -> -1887.4394 | J56: =SUM('Operational Model'!S12:AD13) -> -2393.4112
B57: Gross Profit | I57: =SUM('Operational Model'!G14:R14) -> 10387.748 | J57: =SUM('Operational Model'!S14:AD14) -> 13276.065
B59: Gross Margin | I59: =I57/I55 -> 0.84623947 | J59: =J57/J55 -> 0.84725646
B61: OpEx (Sales & Marketing + R&D/Product + G&A) | I61: =SUM('Operational Model'!G19:R21) -> -11293.285 | J61: =SUM('Operational Model'!S19:AD21) -> -13724.058
B62: EBITDA | I62: =SUM('Operational Model'!G22:R22) -> -905.53701 | J62: =SUM('Operational Model'!S22:AD22) -> -447.99229
B64: EBITDA Margin | I64: =I62/I55 -> -0.07376971 | J64: =J62/J55 -> -0.028590125
...
